<?xml version="1.0" ?>
<!-- =================================================================================== -->
<!-- |    This document was autogenerated by xacro from urdf/freebot_urdf.xacro        | -->
<!-- |    EDITING THIS FILE BY HAND IS NOT RECOMMENDED                                 | -->
<!-- =================================================================================== -->
<robot name="freebot_urdf">
  <material name="Aluminum - Anodized Rough (Grey)">
    <color rgba="0.5372549019607843 0.5372549019607843 0.5372549019607843 1.0"/>
  </material>
  <material name="Steel - Satin">
    <color rgba="0.6274509803921569 0.6274509803921569 0.6274509803921569 1.0"/>
  </material>
  <material name="black">
    <color rgba="0.25098039215686274 0.25098039215686274 0.25098039215686274 1.0"/>
  </material>
  <material name="Opaque(39,196,255)">
    <color rgba="0.15294117647058825 0.7686274509803922 1.0 1.0"/>
  </material>
  <material name="aluminum">
    <color rgba="0.5372549019607843 0.5372549019607843 0.5372549019607843 1.0"/>
  </material>
  <material name="blue2">
    <color rgba="0.058823529411764705 0.8 1.0 1.0"/>
  </material>
  <material name="blue1">
    <color rgba="0.15294117647058825 0.7686274509803922 1.0 1.0"/>
  </material>
  <transmission name="j1_tran">
    <type>transmission_interface/SimpleTransmission</type>
    <joint name="j1">
      <hardwareInterface>hardware_interface/EffortJointInterface</hardwareInterface>
    </joint>
    <actuator name="j1_actr">
      <hardwareInterface>hardware_interface/EffortJointInterface</hardwareInterface>
      <mechanicalReduction>1</mechanicalReduction>
    </actuator>
  </transmission>
  <transmission name="j2_tran">
    <type>transmission_interface/SimpleTransmission</type>
    <joint name="j2">
      <hardwareInterface>hardware_interface/EffortJointInterface</hardwareInterface>
    </joint>
    <actuator name="j2_actr">
      <hardwareInterface>hardware_interface/EffortJointInterface</hardwareInterface>
      <mechanicalReduction>1</mechanicalReduction>
    </actuator>
  </transmission>
  <transmission name="j3_tran">
    <type>transmission_interface/SimpleTransmission</type>
    <joint name="j3">
      <hardwareInterface>hardware_interface/EffortJointInterface</hardwareInterface>
    </joint>
    <actuator name="j3_actr">
      <hardwareInterface>hardware_interface/EffortJointInterface</hardwareInterface>
      <mechanicalReduction>1</mechanicalReduction>
    </actuator>
  </transmission>
  <transmission name="j0_tran">
    <type>transmission_interface/SimpleTransmission</type>
    <joint name="j0">
      <hardwareInterface>hardware_interface/EffortJointInterface</hardwareInterface>
    </joint>
    <actuator name="j0_actr">
      <hardwareInterface>hardware_interface/EffortJointInterface</hardwareInterface>
      <mechanicalReduction>1</mechanicalReduction>
    </actuator>
  </transmission>
  <transmission name="j4_tran">
    <type>transmission_interface/SimpleTransmission</type>
    <joint name="j4">
      <hardwareInterface>hardware_interface/EffortJointInterface</hardwareInterface>
    </joint>
    <actuator name="j4_actr">
      <hardwareInterface>hardware_interface/EffortJointInterface</hardwareInterface>
      <mechanicalReduction>1</mechanicalReduction>
    </actuator>
  </transmission>
  <gazebo>
    <plugin filename="libgazebo_ros_control.so" name="control"/>
  </gazebo>
  <gazebo reference="base_link">
    <material>Gazebo/Silver</material>
    <mu1>0.2</mu1>
    <mu2>0.2</mu2>
    <selfCollide>true</selfCollide>
    <gravity>true</gravity>
  </gazebo>
  <gazebo reference="OS_Shoulder_connector_06c_1">
    <material>Gazebo/Silver</material>
    <mu1>0.2</mu1>
    <mu2>0.2</mu2>
    <selfCollide>true</selfCollide>
  </gazebo>
  <gazebo reference="OS_Connector_shoulder_08_1">
    <material>Gazebo/Silver</material>
    <mu1>0.2</mu1>
    <mu2>0.2</mu2>
    <selfCollide>true</selfCollide>
  </gazebo>
  <gazebo reference="OS_Wrist_connector_01_1">
    <material>Gazebo/Silver</material>
    <mu1>0.2</mu1>
    <mu2>0.2</mu2>
    <selfCollide>true</selfCollide>
  </gazebo>
  <gazebo reference="OS_Shoulder_connector_01d_1">
    <material>Gazebo/Silver</material>
    <mu1>0.2</mu1>
    <mu2>0.2</mu2>
    <selfCollide>true</selfCollide>
  </gazebo>
  <gazebo reference="OS_Tool_Adapter_1">
    <material>Gazebo/Silver</material>
    <mu1>0.2</mu1>
    <mu2>0.2</mu2>
    <selfCollide>true</selfCollide>
  </gazebo>
  <gazebo reference="OS_Upper_arm_tube_1">
    <material>Gazebo/Silver</material>
    <mu1>0.2</mu1>
    <mu2>0.2</mu2>
    <selfCollide>true</selfCollide>
  </gazebo>
  <gazebo reference="OS_Connector_Elbow_07b_1">
    <material>Gazebo/Silver</material>
    <mu1>0.2</mu1>
    <mu2>0.2</mu2>
    <selfCollide>true</selfCollide>
  </gazebo>
  <gazebo reference="OS_Upper_arm_tube_2">
    <material>Gazebo/Silver</material>
    <mu1>0.2</mu1>
    <mu2>0.2</mu2>
    <selfCollide>true</selfCollide>
  </gazebo>
  <gazebo reference="OS_Connector_Elbow_07e_1">
    <material>Gazebo/Silver</material>
    <mu1>0.2</mu1>
    <mu2>0.2</mu2>
    <selfCollide>true</selfCollide>
  </gazebo>
  <link name="/base_link">
    <inertial>
      <origin rpy="0 0 0" xyz="5.788644740024379e-16 -1.1926662407975113e-07 0.019419883704314026"/>
      <mass value="1.0327024293593068"/>
      <inertia ixx="0.001299" ixy="-0.0" ixz="-0.0" iyy="0.001299" iyz="0.0" izz="0.002125"/>
    </inertial>
    <visual>
      <origin rpy="0 0 0" xyz="0 0 0"/>
      <geometry>
        <mesh filename="package://freebot_urdf_description/meshes/base_link_freebot_urdf v0_Body1_base_link.stl" scale="0.001 0.001 0.001"/>
      </geometry>
      <material name="black">
        <color rgba="0.25098039215686274 0.25098039215686274 0.25098039215686274 1.0"/>
      </material>
    </visual>
    <visual>
      <origin rpy="0 0 0" xyz="0 0 0"/>
      <geometry>
        <mesh filename="package://freebot_urdf_description/meshes/base_link_freebot_urdf v0_Body2_base_link.stl" scale="0.001 0.001 0.001"/>
      </geometry>
      <material name="black">
        <color rgba="0.25098039215686274 0.25098039215686274 0.25098039215686274 1.0"/>
      </material>
    </visual>
    <collision>
      <origin rpy="0 0 0" xyz="0 0 0"/>
      <geometry>
        <mesh filename="package://freebot_urdf_description/meshes/base_link.stl" scale="0.001 0.001 0.001"/>
      </geometry>
    </collision>
  </link>
  <link name="/OS_Shoulder_connector_06c_1">
    <inertial>
      <origin rpy="0 0 0" xyz="-0.03039370289078793 1.3251316521099543e-08 0.010093838443597597"/>
      <mass value="0.5649312746649212"/>
      <inertia ixx="0.000733" ixy="0.0" ixz="-4e-06" iyy="0.000572" iyz="-0.0" izz="0.000368"/>
    </inertial>
    <visual>
      <origin rpy="0 0 0" xyz="0.006 0.0 -0.1215"/>
      <geometry>
        <mesh filename="package://freebot_urdf_description/meshes/OS_Shoulder_connector_06c_1_freebot_urdf v0_Body1_OS_Shoulder_connector_06c_1.stl" scale="0.001 0.001 0.001"/>
      </geometry>
      <material name="black">
        <color rgba="0.25098039215686274 0.25098039215686274 0.25098039215686274 1.0"/>
      </material>
    </visual>
    <visual>
      <origin rpy="0 0 0" xyz="0.006 0.0 -0.1215"/>
      <geometry>
        <mesh filename="package://freebot_urdf_description/meshes/OS_Shoulder_connector_06c_1_freebot_urdf v0_Body2_OS_Shoulder_connector_06c_1.stl" scale="0.001 0.001 0.001"/>
      </geometry>
      <material name="blue1">
        <color rgba="0.15294117647058825 0.7686274509803922 1.0 1.0"/>
      </material>
    </visual>
    <collision>
      <origin rpy="0 0 0" xyz="0.006 0.0 -0.1215"/>
      <geometry>
        <mesh filename="package://freebot_urdf_description/meshes/OS_Shoulder_connector_06c_1.stl" scale="0.001 0.001 0.001"/>
      </geometry>
    </collision>
  </link>
  <link name="/OS_Connector_shoulder_08_1">
    <inertial>
      <origin rpy="0 0 0" xyz="0.027309309346106102 -0.013048790283129138 1.9964691722051953e-07"/>
      <mass value="0.4676784438857144"/>
      <inertia ixx="0.000444" ixy="3.4e-05" ixz="-0.0" iyy="0.000267" iyz="0.0" izz="0.000407"/>
    </inertial>
    <visual>
      <origin rpy="0 0 0" xyz="0.0035 0.0 -0.4215"/>
      <geometry>
        <mesh filename="package://freebot_urdf_description/meshes/OS_Connector_shoulder_08_1_freebot_urdf v0_Body1_OS_Connector_shoulder_08_1.stl" scale="0.001 0.001 0.001"/>
      </geometry>
      <material name="black">
        <color rgba="0.25098039215686274 0.25098039215686274 0.25098039215686274 1.0"/>
      </material>
    </visual>
    <visual>
      <origin rpy="0 0 0" xyz="0.0035 0.0 -0.4215"/>
      <geometry>
        <mesh filename="package://freebot_urdf_description/meshes/OS_Connector_shoulder_08_1_freebot_urdf v0_Body2_OS_Connector_shoulder_08_1.stl" scale="0.001 0.001 0.001"/>
      </geometry>
      <material name="blue2">
        <color rgba="0.058823529411764705 0.8 1.0 1.0"/>
      </material>
    </visual>
    <collision>
      <origin rpy="0 0 0" xyz="0.0035 0.0 -0.4215"/>
      <geometry>
        <mesh filename="package://freebot_urdf_description/meshes/OS_Connector_shoulder_08_1.stl" scale="0.001 0.001 0.001"/>
      </geometry>
    </collision>
  </link>
  <link name="/OS_Wrist_connector_01_1">
    <inertial>
      <origin rpy="0 0 0" xyz="0.0285588469364604 -0.0004577057160622955 8.041520321855344e-08"/>
      <mass value="0.4901478983667687"/>
      <inertia ixx="0.000409" ixy="-3e-06" ixz="0.0" iyy="0.000463" iyz="-0.0" izz="0.00043"/>
    </inertial>
    <visual>
      <origin rpy="0 0 0" xyz="-0.0583 0.3 -0.4215"/>
      <geometry>
        <mesh filename="package://freebot_urdf_description/meshes/OS_Wrist_connector_01_1_freebot_urdf v0_Body1_OS_Wrist_connector_01_1.stl" scale="0.001 0.001 0.001"/>
      </geometry>
      <material name="black">
        <color rgba="0.25098039215686274 0.25098039215686274 0.25098039215686274 1.0"/>
      </material>
    </visual>
    <visual>
      <origin rpy="0 0 0" xyz="-0.0583 0.3 -0.4215"/>
      <geometry>
        <mesh filename="package://freebot_urdf_description/meshes/OS_Wrist_connector_01_1_freebot_urdf v0_Body2_OS_Wrist_connector_01_1.stl" scale="0.001 0.001 0.001"/>
      </geometry>
      <material name="blue1">
        <color rgba="0.15294117647058825 0.7686274509803922 1.0 1.0"/>
      </material>
    </visual>
    <collision>
      <origin rpy="0 0 0" xyz="-0.0583 0.3 -0.4215"/>
      <geometry>
        <mesh filename="package://freebot_urdf_description/meshes/OS_Wrist_connector_01_1.stl" scale="0.001 0.001 0.001"/>
      </geometry>
    </collision>
  </link>
  <link name="/OS_Shoulder_connector_01d_1">
    <inertial>
      <origin rpy="0 0 0" xyz="0.012959388753636114 2.1853349424144736e-08 0.04081897310032624"/>
      <mass value="0.7652200389336291"/>
      <inertia ixx="0.001161" ixy="0.0" ixz="-0.000189" iyy="0.001026" iyz="-0.0" izz="0.00086"/>
    </inertial>
    <visual>
      <origin rpy="0 0 0" xyz="0.0 0.0 -0.0605"/>
      <geometry>
        <mesh filename="package://freebot_urdf_description/meshes/OS_Shoulder_connector_01d_1_freebot_urdf v0_Body1_OS_Shoulder_connector_01d_1.stl" scale="0.001 0.001 0.001"/>
      </geometry>
      <material name="blue1">
        <color rgba="0.15294117647058825 0.7686274509803922 1.0 1.0"/>
      </material>
    </visual>
    <visual>
      <origin rpy="0 0 0" xyz="0.0 0.0 -0.0605"/>
      <geometry>
        <mesh filename="package://freebot_urdf_description/meshes/OS_Shoulder_connector_01d_1_freebot_urdf v0_Body2_OS_Shoulder_connector_01d_1.stl" scale="0.001 0.001 0.001"/>
      </geometry>
      <material name="black">
        <color rgba="0.25098039215686274 0.25098039215686274 0.25098039215686274 1.0"/>
      </material>
    </visual>
    <collision>
      <origin rpy="0 0 0" xyz="0.0 0.0 -0.0605"/>
      <geometry>
        <mesh filename="package://freebot_urdf_description/meshes/OS_Shoulder_connector_01d_1.stl" scale="0.001 0.001 0.001"/>
      </geometry>
    </collision>
  </link>
  <link name="/OS_Tool_Adapter_1">
    <inertial>
      <origin rpy="0 0 0" xyz="2.4091839634365897e-14 -0.012369036341301598 -8.212593333412066e-05"/>
      <mass value="0.4113331685848012"/>
      <inertia ixx="0.000148" ixy="0.0" ixz="-0.0" iyy="0.000256" iyz="-0.0" izz="0.000149"/>
    </inertial>
    <visual>
      <origin rpy="0 0 0" xyz="-0.0943 0.3385 -0.4215"/>
      <geometry>
        <mesh filename="package://freebot_urdf_description/meshes/OS_Tool_Adapter_1_freebot_urdf v0_Body1_OS_Tool_Adapter_1.stl" scale="0.001 0.001 0.001"/>
      </geometry>
      <material name="aluminum">
        <color rgba="0.5372549019607843 0.5372549019607843 0.5372549019607843 1.0"/>
      </material>
    </visual>
    <collision>
      <origin rpy="0 0 0" xyz="-0.0943 0.3385 -0.4215"/>
      <geometry>
        <mesh filename="package://freebot_urdf_description/meshes/OS_Tool_Adapter_1.stl" scale="0.001 0.001 0.001"/>
      </geometry>
    </collision>
  </link>
  <link name="/OS_Upper_arm_tube_1">
    <inertial>
      <origin rpy="0 0 0" xyz="-3.885780586188048e-16 -1.813439160552377e-15 0.11050000000000013"/>
      <mass value="0.4257953995856516"/>
      <inertia ixx="0.001862" ixy="0.0" ixz="0.0" iyy="0.001862" iyz="0.0" izz="0.000258"/>
    </inertial>
    <visual>
      <origin rpy="0 0 0" xyz="0.0344 0.0 -0.1635"/>
      <geometry>
        <mesh filename="package://freebot_urdf_description/meshes/OS_Upper_arm_tube_1_freebot_urdf v0_Body1_OS_Upper_arm_tube_1.stl" scale="0.001 0.001 0.001"/>
      </geometry>
      <material name="aluminum">
        <color rgba="0.5372549019607843 0.5372549019607843 0.5372549019607843 1.0"/>
      </material>
    </visual>
    <collision>
      <origin rpy="0 0 0" xyz="0.0344 0.0 -0.1635"/>
      <geometry>
        <mesh filename="package://freebot_urdf_description/meshes/OS_Upper_arm_tube_1.stl" scale="0.001 0.001 0.001"/>
      </geometry>
    </collision>
  </link>
  <link name="/OS_Connector_Elbow_07b_1">
    <inertial>
      <origin rpy="0 0 0" xyz="0.00031605452176478727 2.1925606150479413e-07 0.02489388503643264"/>
      <mass value="0.45527867911642017"/>
      <inertia ixx="0.00047" ixy="0.0" ixz="-1e-06" iyy="0.000412" iyz="-0.0" izz="0.00028"/>
    </inertial>
    <visual>
      <origin rpy="0 0 0" xyz="0.0344 0.0 -0.3845"/>
      <geometry>
        <mesh filename="package://freebot_urdf_description/meshes/OS_Connector_Elbow_07b_1_freebot_urdf v0_Body1_OS_Connector_Elbow_07b_1.stl" scale="0.001 0.001 0.001"/>
      </geometry>
      <material name="black">
        <color rgba="0.25098039215686274 0.25098039215686274 0.25098039215686274 1.0"/>
      </material>
    </visual>
    <visual>
      <origin rpy="0 0 0" xyz="0.0344 0.0 -0.3845"/>
      <geometry>
        <mesh filename="package://freebot_urdf_description/meshes/OS_Connector_Elbow_07b_1_freebot_urdf v0_Body2_OS_Connector_Elbow_07b_1.stl" scale="0.001 0.001 0.001"/>
      </geometry>
      <material name="blue1">
        <color rgba="0.15294117647058825 0.7686274509803922 1.0 1.0"/>
      </material>
    </visual>
    <collision>
      <origin rpy="0 0 0" xyz="0.0344 0.0 -0.3845"/>
      <geometry>
        <mesh filename="package://freebot_urdf_description/meshes/OS_Connector_Elbow_07b_1.stl" scale="0.001 0.001 0.001"/>
      </geometry>
    </collision>
  </link>
  <link name="/OS_Upper_arm_tube_2">
    <inertial>
      <origin rpy="0 0 0" xyz="-1.0304257447302234e-15 -0.11050000000000368 -1.9984014443252818e-15"/>
      <mass value="0.4257953995856516"/>
      <inertia ixx="0.001862" ixy="-0.0" ixz="0.0" iyy="0.000258" iyz="-0.0" izz="0.001862"/>
    </inertial>
    <visual>
      <origin rpy="0 0 0" xyz="-0.0274 0.038 -0.4215"/>
      <geometry>
        <mesh filename="package://freebot_urdf_description/meshes/OS_Upper_arm_tube_2_freebot_urdf v0_Body1_OS_Upper_arm_tube_2.stl" scale="0.001 0.001 0.001"/>
      </geometry>
      <material name="aluminum">
        <color rgba="0.5372549019607843 0.5372549019607843 0.5372549019607843 1.0"/>
      </material>
    </visual>
    <collision>
      <origin rpy="0 0 0" xyz="-0.0274 0.038 -0.4215"/>
      <geometry>
        <mesh filename="package://freebot_urdf_description/meshes/OS_Upper_arm_tube_2.stl" scale="0.001 0.001 0.001"/>
      </geometry>
    </collision>
  </link>
  <link name="/OS_Connector_Elbow_07e_1">
    <inertial>
      <origin rpy="0 0 0" xyz="-0.0028719702836169196 -0.027561945003886867 5.652840506797929e-08"/>
      <mass value="0.5104652508454282"/>
      <inertia ixx="0.000561" ixy="-2.9e-05" ixz="-0.0" iyy="0.000353" iyz="-0.0" izz="0.000515"/>
    </inertial>
    <visual>
      <origin rpy="0 0 0" xyz="-0.0274 0.259 -0.4215"/>
      <geometry>
        <mesh filename="package://freebot_urdf_description/meshes/OS_Connector_Elbow_07e_1_freebot_urdf v0_Body1_OS_Connector_Elbow_07e_1.stl" scale="0.001 0.001 0.001"/>
      </geometry>
      <material name="black">
        <color rgba="0.25098039215686274 0.25098039215686274 0.25098039215686274 1.0"/>
      </material>
    </visual>
    <visual>
      <origin rpy="0 0 0" xyz="-0.0274 0.259 -0.4215"/>
      <geometry>
        <mesh filename="package://freebot_urdf_description/meshes/OS_Connector_Elbow_07e_1_freebot_urdf v0_Body2_OS_Connector_Elbow_07e_1.stl" scale="0.001 0.001 0.001"/>
      </geometry>
      <material name="blue1">
        <color rgba="0.15294117647058825 0.7686274509803922 1.0 1.0"/>
      </material>
    </visual>
    <collision>
      <origin rpy="0 0 0" xyz="-0.0274 0.259 -0.4215"/>
      <geometry>
        <mesh filename="package://freebot_urdf_description/meshes/OS_Connector_Elbow_07e_1.stl" scale="0.001 0.001 0.001"/>
      </geometry>
    </collision>
  </link>
  <joint name="j1" type="continuous">
    <origin rpy="0 0 0" xyz="-0.006 0.0 0.061"/>
    <parent link="/OS_Shoulder_connector_01d_1"/>
    <child link="/OS_Shoulder_connector_06c_1"/>
    <axis xyz="-1.0 0.0 -0.0"/>
  </joint>
  <joint name="j2" type="continuous">
    <origin rpy="0 0 0" xyz="0.0309 0.0 0.037"/>
    <parent link="/OS_Connector_Elbow_07b_1"/>
    <child link="/OS_Connector_shoulder_08_1"/>
    <axis xyz="1.0 -0.0 0.0"/>
  </joint>
  <joint name="j3" type="continuous">
    <origin rpy="0 0 0" xyz="0.0309 -0.041 0.0"/>
    <parent link="/OS_Connector_Elbow_07e_1"/>
    <child link="/OS_Wrist_connector_01_1"/>
    <axis xyz="-1.0 0.0 -0.0"/>
  </joint>
  <joint name="j0" type="continuous">
    <origin rpy="0 0 0" xyz="0.0 0.0 0.0605"/>
    <parent link="/base_link"/>
    <child link="/OS_Shoulder_connector_01d_1"/>
    <axis xyz="0.0 0.0 -1.0"/>
  </joint>
  <joint name="j4" type="continuous">
    <origin rpy="0 0 0" xyz="0.036 -0.0385 0.0"/>
    <parent link="/OS_Wrist_connector_01_1"/>
    <child link="/OS_Tool_Adapter_1"/>
    <axis xyz="-0.0 -1.0 -0.0"/>
  </joint>
  <joint name="Rigid10" type="fixed">
    <origin rpy="0 0 0" xyz="-0.0284 0.0 0.042"/>
    <parent link="/OS_Shoulder_connector_06c_1"/>
    <child link="/OS_Upper_arm_tube_1"/>
  </joint>
  <joint name="Rigid11" type="fixed">
    <origin rpy="0 0 0" xyz="0.0 0.0 0.221"/>
    <parent link="/OS_Upper_arm_tube_1"/>
    <child link="/OS_Connector_Elbow_07b_1"/>
  </joint>
  <joint name="Rigid12" type="fixed">
    <origin rpy="0 0 0" xyz="0.0309 -0.038 0.0"/>
    <parent link="/OS_Connector_shoulder_08_1"/>
    <child link="/OS_Upper_arm_tube_2"/>
  </joint>
  <joint name="Rigid13" type="fixed">
    <origin rpy="0 0 0" xyz="0.0 -0.221 0.0"/>
    <parent link="/OS_Upper_arm_tube_2"/>
    <child link="/OS_Connector_Elbow_07e_1"/>
  </joint>
</robot>

